Workbook

Sheet Tutte le stem
A1: Classe di laurea | B1: Numero di laureati | C1: Numero di intervistati | D1: Tasso di risposta sui laureati contattabili | E1: età alla laurea | F1: voto di laurea | G1: indice di ritardo | H1: % Uomini | I1: % Donne | J1: durata degli studi | K1: tasso di occupazione | L1: tempo dall'inizio della ricerca al reperimento del primo lavoro | M1: tempo indeterminato | N1: numero di ore di lavoro settimanali | O1: gender gap retribuzione | P1: retribuzione mensile netta totale | Q1: utilizzo elevato delle competenze acquisite | R1: adeguatezza della formazione professionale acquisita all'università : molto adeguata | S1: laurea molto efficace per il lavoro svolto | T1: soddisfazione lavoro svolto | U1: occupati che cercano lavoro | V1: diffusione smart working | W1: retribuzione mensile netta uomini | X1: retribuzione mensile netta donne | Y1: laurea abbastanza efficace per il lavoro svolto
A2: Biologia LM-6 | B2: 3238 | C2: 1673 | D2: 67.5 | E2: 27.1 | F2: 109 | G2: 0.19 | H2: 27.2 | I2: 72.8 | J2: 2.7 | K2: 84.5 | L2: 7.1 | M2: 30.3 | N2: 34.1 | O2: 106.9 | P2: 1387 | Q2: 53.1 | R2: 57.5 | S2: 73.2 | T2: 7.9 | U2: 22.4 | V2: 25.1 | W2: 1459 | X2: 1365 | Y2: 17.3
A3: Biotecnologie mediche veterinarie e farmaceutiche LM-9 | B3: 1271 | C3: 654 | D3: 68.9 | E3: 26.3 | F3: 109.7 | G3: 0.11 | H3: 29 | I3: 71 | J3: 2.4 | K3: 88.5 | L3: 5.9 | M3: 43.9 | N3: 38.3 | O3: 106.1 | P3: 1475 | Q3: 54.4 | R3: 57.5 | S3: 69.4 | T3: 7.8 | U3: 23.5 | V3: 28.5 | W3: 1539 | X3: 1450 | Y3: 20.5
A4: Scienze Chimiche LM-54 | B4: 979 | C4: 512 | D4: 71.5 | E4: 26.3 | F4: 109.4 | G4: 0.15 | H4: 52.1 | I4: 47.9 | J4: 2.5 | K4: 89.5 | L4: 4.1 | M4: 54.2 | N4: 39.1 | O4: 106.4 | P4: 1538 | Q4: 54.2 | R4: 58.9 | S4: 61.7 | T4: 7.7 | U4: 20.3 | V4: 24.1 | W4: 1585 | X4: 1490 | Y4: 29
A5: scienze della nutrizione umana LM-61 | B5: 801 | C5: 442 | D5: 68.4 | E5: 27.9 | F5: 107.5 | G5: 0.13 | H5: 19.5 | I5: 80.5 | J5: 2.5 | K5: 90 | L5: 5.8 | M5: 18 | N5: 32.9 | O5: 112 | P5: 1399 | Q5: 67.7 | R5: 62.1 | S5: 84.6 | T5: 8.2 | U5: 20.4 | V5: 23.4 | W5: 1536 | X5: 1372 | Y5: 10.2
A6: biotecnologie industriali LM-8 | B6: 405 | C6: 230 | D6: 70.1 | E6: 26.3 | F6: 109 | G6: 0.14 | H6: 38 | I6: 62 | J6: 2.5 | K6: 90.9 | L6: 5.2 | M6: 45.9 | N6: 38.2 | O6: 106.3 | P6: 1519 | Q6: 43.2 | R6: 53.2 | S6: 56.9 | T6: 7.6 | U6: 30.8 | V6: 31.5 | W6: 1572 | X6: 1479 | Y6: 31.2
A7: Scienze della natura LM-60 | B7: 245 | C7: 123 | D7: 67.6 | E7: 27.2 | F7: 110.3 | G7: 0.18 | H7: 41.6 | I7: 58.4 | J7: 2.7 | K7: 83.7 | L7: 6.6 | M7: 17.3 | N7: 25.4 | O7: 114 | P7: 1193 | Q7: 60.5 | R7: 53.1 | S7: 70.5 | T7: 7.7 | U7: 34.9 | V7: 38.3 | W7: 1278 | X7: 1121 | Y7: 14.1
A8: conservazione e restauro dei beni culturali LM-11 | B8: 93 | C8: 42 | D8: 59.2 | E8: 27 | F8: 110.3 | G8: 0.11 | H8: 18.3 | I8: 81.7 | J8: 2.5 | K8: 73.8 | L8: 8.3 | M8: 16.7 | N8: 35.5 | O8: 244.5 | P8: 1442 | Q8: 27.8 | R8: 38.9 | S8: 31.3 | T8: 7.4 | U8: 47.6 | V8: 16.7 | W8: 3250 | X8: 1329 | Y8: 25
A9: Scienze dell'universo LM-58 | B9: 89 | C9: 42 | D9: 61.8 | E9: 26.6 | F9: 108.9 | G9: 0.18 | H9: 50.6 | I9: 49.4 | J9: 2.6 | K9: 88.1 | L9: 4.8 | M9: 50 | N9: 32.4 | O9: 93.1 | P9: 1491 | Q9: 35.7 | R9: 35.7 | S9: 46.2 | T9: 7.8 | U9: 10.5 | V9: 42.9 | W9: 1426 | X9: 1532 | Y9: 23.1
A10: Informatica LM-18 | B10: 840 | C10: 360 | D10: 63.5 | E10: 27.2 | F10: 108 | G10: 0.31 | H10: 81.9 | I10: 18.1 | J10: 2.9 | K10: 97.2 | L10: 1.9 | M10: 77.2 | N10: 40.9 | O10: 110.9 | P10: 1873 | Q10: 63.2 | R10: 71.6 | S10: 66 | T10: 7.8 | U10: 13.4 | V10: 79.6 | W10: 1902 | X10: 1715 | Y10: 29.8
A11: scienze e tecnologie geologiche LM-74 | B11: 660 | C11: 369 | D11: 70.3 | E11: 27 | F11: 108.8 | G11: 0.2 | H11: 63.6 | I11: 36.4 | J11: 2.7 | K11: 84.3 | L11: 5.4 | M11: 35.3 | N11: 37.7 | O11: 108.7 | P11: 1407 | Q11: 48.2 | R11: 50 | S11: 64.1 | T11: 7.8 | U11: 26.4 | V11: 38.4 | W11: 1443 | X11: 1328 | Y11: 25.9
A12: scienze e tecnologie ambiente e territorio LM-75 | B12: 388 | C12: 187 | D12: 63.6 | E12: 27.4 | F12: 110 | G12: 0.15 | H12: 47.2 | I12: 52.8 | J12: 2.6 | K12: 87.2 | L12: 4.6 | M12: 38 | N12: 34.5 | O12: 112.8 | P12: 1387 | Q12: 44.2 | R12: 55.8 | S12: 58.7 | T12: 7.7 | U12: 23.3 | V12: 34.9 | W12: 1471 | X12: 1304 | Y12: 27
A13: scienze e tecnologie della chimica industriale LM-71 | B13: 283 | C13: 144 | D13: 72 | E13: 26.1 | F13: 107.8 | G13: 0.16 | H13: 61.1 | I13: 38.9 | J13: 2.5 | K13: 91.7 | L13: 4.1 | M13: 62.2 | N13: 40.7 | O13: 94 | P13: 1529 | Q13: 55.6 | R13: 65.6 | S13: 61.8 | T13: 7.6 | U13: 27.4 | V13: 26.7 | W13: 1488 | X13: 1583 | Y13: 30.3
... A37: Fisica LM-17 | B37: 999 | C37: 543 | D37: 73.5 | E37: 26.1 | F37: 110.3 | G37: 0.23 | H37: 72 | I37: 28 | J37: 2.7 | K37: 95.6 | L37: 2.9 | M37: 52.8 | N37: 37.2 | O37: 107.8 | P37: 1633 | Q37: 47.8 | R37: 63.9 | S37: 61.3 | T37: 8 | U37: 14.9 | V37: 63.9 | W37: 1666 | X37: 1546 | Y37: 32.9
A39: Indici di posizione | B39: Numero di laureati | C39: Numero di intervistati | D39: Tasso di risposta sui laureati contattabili | E39: età alla laurea | F39: voto di laurea | G39: indice di ritardo | H39: % Uomini | I39: % Donne | J39: durata degli studi | K39: tasso di occupazione | L39: tempo dall'inizio della ricerca al reperimento del primo lavoro | M39: tempo indeterminato | N39: numero di ore di lavoro settimanali | O39: gender gap retribuzione | P39: retribuzione mensile netta totale | Q39: utilizzo elevato delle competenze acquisite | R39: adeguatezza della formazione professionale acquisita all'università : molto adeguata | S39: laurea molto efficace per il lavoro svolto | T39: soddisfazione lavoro svolto | U39: occupati che cercano lavoro | V39: diffusione smart working | W39: retribuzione mensile netta uomini | X39: retribuzione mensile netta donne | Y39: laurea abbastanza efficace per il lavoro svolto
A40: MEDIA | B40: =AVERAGE(B2:B37) -> 828.88889 | C40: =AVERAGE(C2:C37) -> 432.44444 | D40: =AVERAGE(D2:D37) -> 68.941667 | E40: =AVERAGE(E2:E37) -> 27.022222 | F40: =AVERAGE(F2:F37) -> 107.82222 | G40: =AVERAGE(G2:G37) -> 0.25 | H40: =AVERAGE(H2:H37) -> 59.369444 | I40: =AVERAGE(I2:I37) -> 40.630556 | ... Y40: =AVERAGE(Y2:Y37) -> 28.633333
A41: MEDIANA | B41: =MEDIAN(B2:B37) -> 642 | C41: =MEDIAN(C2:C37) -> 347 | D41: =MEDIAN(D2:D37) -> 69.9 | E41: =MEDIAN(E2:E37) -> 26.8 | F41: =MEDIAN(F2:F37) -> 107.65 | G41: =MEDIAN(G2:G37) -> 0.235 | H41: =MEDIAN(H2:H37) -> 58.85 | I41: =MEDIAN(I2:I37) -> 41.15 | ... Y41: =MEDIAN(Y2:Y37) -> 29.25
A42: VALORE MINIMO | B42: =MIN(B2:B37) -> 88 | C42: =MIN(C2:C37) -> 42 | D42: =MIN(D2:D37) -> 56.6 | E42: =MIN(E2:E37) -> 26 | F42: =MIN(F2:F37) -> 105.3 | G42: =MIN(G2:G37) -> 0.11 | H42: =MIN(H2:H37) -> 18.3 | I42: =MIN(I2:I37) -> 7.8 | ... Y42: =MIN(Y2:Y37) -> 10.2
A43: VALORE MASSIMO | B43: =MAX(B2:B37) -> 3238 | C43: =MAX(C2:C37) -> 1673 | D43: =MAX(D2:D37) -> 85.1 | E43: =MAX(E2:E37) -> 30.3 | F43: =MAX(F2:F37) -> 110.3 | G43: =MAX(G2:G37) -> 0.49 | H43: =MAX(H2:H37) -> 92.2 | I43: =MAX(I2:I37) -> 81.7 | ... Y43: =MAX(Y2:Y37) -> 43.3
A44: DEVIAZIONE STANDARD | B44: =_xlfn.STDEV.P(B2:B37) -> 744.07175 | C44: =_xlfn.STDEV.P(C2:C37) -> 389.84038 | D44: =_xlfn.STDEV.P(D2:D37) -> 5.3907006 | E44: =_xlfn.STDEV.P(E2:E37) -> 0.88163709 | F44: =_xlfn.STDEV.P(F2:F37) -> 1.5204369 | G44: =_xlfn.STDEV.P(G2:G37) -> 0.09171211 | H44: =_xlfn.STDEV.P(H2:H37) -> 19.955309 | I44: =_xlfn.STDEV.P(I2:I37) -> 19.955309 | ... Y44: =_xlfn.STDEV.P(Y2:Y37) -> 7.8157604
A45: COEFFICIENTE DI VARIAZIONE | B45: =B44/B40 -> 0.89767369 | C45: =C44/C40 -> 0.90148085 | D45: =D44/D40 -> 0.0781922 | E45: =E44/E40 -> 0.032626372 | F45: =F44/F40 -> 0.014101332 | G45: =G44/G40 -> 0.36684844 | H45: =H44/H40 -> 0.33612086 | I45: =I44/I40 -> 0.49114043 | ... Y45: =Y44/Y40 -> 0.2729602
A46: PRIMO QUARTILE | B46: =QUARTILE(B2:B37,1) -> 307 | C46: =QUARTILE(C2:C37,1) -> 157.5 | D46: =QUARTILE(D2:D37,1) -> 65 | E46: =QUARTILE(E2:E37,1) -> 26.4 | F46: =QUARTILE(F2:F37,1) -> 106.775 | G46: =QUARTILE(G2:G37,1) -> 0.18 | H46: =QUARTILE(H2:H37,1) -> 46.75 | I46: =QUARTILE(I2:I37,1) -> 22.425 | ... Y46: =QUARTILE(Y2:Y37,1) -> 24.525
A47: TERZO QUARTILE | B47: =QUARTILE(B2:B37,3) -> 984 | C47: =QUARTILE(C2:C37,3) -> 519.75 | D47: =QUARTILE(D2:D37,3) -> 71.925 | E47: =QUARTILE(E2:E37,3) -> 27.4 | F47: =QUARTILE(F2:F37,3) -> 109 | G47: =QUARTILE(G2:G37,3) -> 0.315 | H47: =QUARTILE(H2:H37,3) -> 77.575 | I47: =QUARTILE(I2:I37,3) -> 53.25 | ... Y47: =QUARTILE(Y2:Y37,3) -> 33.425
A48: MODA | B48: =MODE(B2:B37) -> 210 | C48: =MODE(C2:C37) -> 42 | D48: =MODE(D2:D37) -> 73.5 | E48: =MODE(E2:E37) -> 26.4 | F48: =MODE(F2:F37) -> 109 | G48: =MODE(G2:G37) -> 0.21 | H48: =MODE(H2:H37) -> 63.6 | I48: =MODE(I2:I37) -> 36.4 | ... Y48: =MODE(Y2:Y37) -> #N/A
A52: Legenda Colori delle STEM
A53: CLASSI DI LAUREA DEL GRUPPO DISCIPLINARE SCIENTIFICO
A54: CLASSI DI LAUREA DEL GRUPPO DISCIPLINARE TECNOLOGICO
A55: CLASSI DI LAUREA DEL GRUPPO DISCIPLINARE INGEGNERIA
A56: CLASSI DI LAUREA DEL GRUPPO DISCIPLINARE MATEMATICO
A58: 36 CLASSI DI LAUREA
A59: 8 CLASSI DI LAUREA DEL GRUPPO SCIENTIFICO
A60: 6 CLASSI DI LAUREA DEL GRUPPO TECNOLOGICO
A61: 20 CLASSI DI LAUREA DEL GRUPPO INGEGNERIA
A62: 2 CLASSI DI LAUREA DEL GRUPPO MATEMATICO

Sheet STEM non analizzate
A1: Classe di Laurea | B1: Numero di Laureati | C1: Tasso di risposta sui laureati contattabili
A2: LM-44 Lauree Magistrali in Modellistica Matematico-Fisica per l'ingegneria | B2: 135 | C2: 0.336
A3: LM-66 Lauree Magistrali in Sicurezza Informatica | B3: 28 | C3: 0.8
A4: LM-72 Scienze e Tecnologie della Navigazione | B4: 17 | C4: 0.765
A5: LM-91 Tecniche e Metodi per La società dell'informazione | B5: 30 | C5: 0.565
A6: LM-79 Lauree Magistrali in Scienze Geofisiche | B6: 24 | C6: 0.706

Sheet Singoli gruppi STEM
A1: Gruppo disciplinare Scientifico | B1: età alla laurea | C1: voto di laurea | D1: indice di ritardo | E1: tasso di occupazione | F1: tempo dall'inizio della ricerca al reperimento del primo lavoro | G1: tempo indeterminato | H1: numero di ore di lavoro settimanali | I1: gender gap retribuzione | J1: retribuzione mensile netta totale | K1: utilizzo elevato delle competenze acquisite | L1: adeguatezza della formazione professionale acquisita all'università : molto adeguata | M1: laurea molto efficace per il lavoro svolto | N1: soddisfazione lavoro svolto | O1: occupati che cercano lavoro | P1: Numero di laureati | Q1: Numero di intervistati | R1: Tasso di risposta sui laureati contattabili | S1: % Uomini | T1: % Donne | U1: durata degli studi | V1: diffusione smart working | W1: retribuzione mensile netta uomini | X1: retribuzione mensile netta donne | Y1: laurea abbastanza efficace per il lavoro svolto
A2: MEDIA | B2: =AVERAGE('Tutte le stem'!E2:E9) -> 26.8375 | C2: =AVERAGE('Tutte le stem'!F2:F9) -> 109.2625 | D2: =AVERAGE('Tutte le stem'!G2:G9) -> 0.14875 | E2: =AVERAGE('Tutte le stem'!K2:K9) -> 86.125 | F2: =AVERAGE('Tutte le stem'!L2:L9) -> 5.975 | G2: =AVERAGE('Tutte le stem'!M2:M9) -> 34.5375 | H2: =AVERAGE('Tutte le stem'!N2:N9) -> 34.4875 | I2: =AVERAGE('Tutte le stem'!O2:O9) -> 123.6625 | J2: =AVERAGE('Tutte le stem'!P2:P9) -> 1430.5 | K2: =AVERAGE('Tutte le stem'!Q2:Q9) -> 49.575 | L2: =AVERAGE('Tutte le stem'!R2:R9) -> 52.1125 | ... O2: =AVERAGE('Tutte le stem'!U2:U9) -> 26.3 | P2: =AVERAGE('Tutte le stem'!B2:B9) -> 890.125 | Q2: =AVERAGE('Tutte le stem'!C2:C9) -> 464.75 | R2: =AVERAGE('Tutte le stem'!D2:D9) -> 66.875 | S2: =AVERAGE('Tutte le stem'!H2:H9) -> 34.5375 | T2: =AVERAGE('Tutte le stem'!I2:I9) -> 65.4625 | U2: =AVERAGE('Tutte le stem'!J2:J9) -> 2.55 | V2: =AVERAGE('Tutte le stem'!V2:V9) -> 28.8125 | W2: =AVERAGE('Tutte le stem'!W2:W9) -> 1705.625 | X2: =AVERAGE('Tutte le stem'!X2:X9) -> 1392.25 | Y2: =AVERAGE('Tutte le stem'!Y2:Y9) -> 21.3
A3: MEDIANA | B3: =MEDIAN('Tutte le stem'!E2:E9) -> 26.8 | C3: =MEDIAN('Tutte le stem'!F2:F9) -> 109.2 | D3: =MEDIAN('Tutte le stem'!G2:G9) -> 0.145 | E3: =MEDIAN('Tutte le stem'!K2:K9) -> 88.3 | F3: =MEDIAN('Tutte le stem'!L2:L9) -> 5.85 | G3: =MEDIAN('Tutte le stem'!M2:M9) -> 37.1 | H3: =MEDIAN('Tutte le stem'!N2:N9) -> 34.8 | I3: =MEDIAN('Tutte le stem'!O2:O9) -> 106.65 | J3: =MEDIAN('Tutte le stem'!P2:P9) -> 1458.5 | K3: =MEDIAN('Tutte le stem'!Q2:Q9) -> 53.65 | L3: =MEDIAN('Tutte le stem'!R2:R9) -> 55.35 | ... O3: =MEDIAN('Tutte le stem'!U2:U9) -> 22.95 | P3: =MEDIAN('Tutte le stem'!B2:B9) -> 603 | Q3: =MEDIAN('Tutte le stem'!C2:C9) -> 336 | R3: =MEDIAN('Tutte le stem'!D2:D9) -> 68 | S3: =MEDIAN('Tutte le stem'!H2:H9) -> 33.5 | T3: =MEDIAN('Tutte le stem'!I2:I9) -> 66.5 | U3: =MEDIAN('Tutte le stem'!J2:J9) -> 2.5 | V3: =MEDIAN('Tutte le stem'!V2:V9) -> 26.8 | W3: =MEDIAN('Tutte le stem'!W2:W9) -> 1537.5 | X3: =MEDIAN('Tutte le stem'!X2:X9) -> 1411 | Y3: =MEDIAN('Tutte le stem'!Y2:Y9) -> 21.8
A4: VALORE MINIMO | B4: =MIN('Tutte le stem'!E2:E9) -> 26.3 | C4: =MIN('Tutte le stem'!F2:F9) -> 107.5 | D4: =MIN('Tutte le stem'!G2:G9) -> 0.11 | E4: =MIN('Tutte le stem'!K2:K9) -> 73.8 | F4: =MIN('Tutte le stem'!L2:L9) -> 4.1 | G4: =MIN('Tutte le stem'!M2:M9) -> 16.7 | H4: =MIN('Tutte le stem'!N2:N9) -> 25.4 | I4: =MIN('Tutte le stem'!O2:O9) -> 93.1 | J4: =MIN('Tutte le stem'!P2:P9) -> 1193 | K4: =MIN('Tutte le stem'!Q2:Q9) -> 27.8 | L4: =MIN('Tutte le stem'!R2:R9) -> 35.7 | ... O4: =MIN('Tutte le stem'!U2:U9) -> 10.5 | P4: =MIN('Tutte le stem'!B2:B9) -> 89 | Q4: =MIN('Tutte le stem'!C2:C9) -> 42 | R4: =MIN('Tutte le stem'!D2:D9) -> 59.2 | S4: =MIN('Tutte le stem'!H2:H9) -> 18.3 | T4: =MIN('Tutte le stem'!I2:I9) -> 47.9 | U4: =MIN('Tutte le stem'!J2:J9) -> 2.4 | V4: =MIN('Tutte le stem'!V2:V9) -> 16.7 | W4: =MIN('Tutte le stem'!W2:W9) -> 1278 | X4: =MIN('Tutte le stem'!X2:X9) -> 1121 | Y4: =MIN('Tutte le stem'!Y2:Y9) -> 10.2
A5: VALORE MASSIMO | B5: =MAX('Tutte le stem'!E2:E9) -> 27.9 | C5: =MAX('Tutte le stem'!F2:F9) -> 110.3 | D5: =MAX('Tutte le stem'!G2:G9) -> 0.19 | E5: =MAX('Tutte le stem'!K2:K9) -> 90.9 | F5: =MAX('Tutte le stem'!L2:L9) -> 8.3 | G5: =MAX('Tutte le stem'!M2:M9) -> 54.2 | H5: =MAX('Tutte le stem'!N2:N9) -> 39.1 | I5: =MAX('Tutte le stem'!O2:O9) -> 244.5 | J5: =MAX('Tutte le stem'!P2:P9) -> 1538 | K5: =MAX('Tutte le stem'!Q2:Q9) -> 67.7 | L5: =MAX('Tutte le stem'!R2:R9) -> 62.1 | ... O5: =MAX('Tutte le stem'!U2:U9) -> 47.6 | P5: =MAX('Tutte le stem'!B2:B9) -> 3238 | Q5: =MAX('Tutte le stem'!C2:C9) -> 1673 | R5: =MAX('Tutte le stem'!D2:D9) -> 71.5 | S5: =MAX('Tutte le stem'!H2:H9) -> 52.1 | T5: =MAX('Tutte le stem'!I2:I9) -> 81.7 | U5: =MAX('Tutte le stem'!J2:J9) -> 2.7 | V5: =MAX('Tutte le stem'!V2:V9) -> 42.9 | W5: =MAX('Tutte le stem'!W2:W9) -> 3250 | X5: =MAX('Tutte le stem'!X2:X9) -> 1532 | Y5: =MAX('Tutte le stem'!Y2:Y9) -> 31.2
A6: DEVIAZIONE STANDARD | B6: =_xlfn.STDEV.P('Tutte le stem'!E2:E9) -> 0.53370755 | C6: =_xlfn.STDEV.P('Tutte le stem'!F2:F9) -> 0.84696148 | D6: =_xlfn.STDEV.P('Tutte le stem'!G2:G9) -> 0.029764702 | E6: =_xlfn.STDEV.P('Tutte le stem'!K2:K9) -> 5.2342024 | F6: =_xlfn.STDEV.P('Tutte le stem'!L2:L9) -> 1.254741 | G6: =_xlfn.STDEV.P('Tutte le stem'!M2:M9) -> 14.786898 | H6: =_xlfn.STDEV.P('Tutte le stem'!N2:N9) -> 4.1867163 | I6: =_xlfn.STDEV.P('Tutte le stem'!O2:O9) -> 46.035338 | J6: =_xlfn.STDEV.P('Tutte le stem'!P2:P9) -> 102.74483 | K6: =_xlfn.STDEV.P('Tutte le stem'!Q2:Q9) -> 12.30993 | L6: =_xlfn.STDEV.P('Tutte le stem'!R2:R9) -> 9.0136615 | ... O6: =_xlfn.STDEV.P('Tutte le stem'!U2:U9) -> 10.555804 | P6: =_xlfn.STDEV.P('Tutte le stem'!B2:B9) -> 974.81837 | Q6: =_xlfn.STDEV.P('Tutte le stem'!C2:C9) -> 503.45922 | R6: =_xlfn.STDEV.P('Tutte le stem'!D2:D9) -> 3.9337482 | S6: =_xlfn.STDEV.P('Tutte le stem'!H2:H9) -> 12.260703 | T6: =_xlfn.STDEV.P('Tutte le stem'!I2:I9) -> 12.260703 | U6: =_xlfn.STDEV.P('Tutte le stem'!J2:J9) -> 0.1 | V6: =_xlfn.STDEV.P('Tutte le stem'!V2:V9) -> 7.9670317 | W6: =_xlfn.STDEV.P('Tutte le stem'!W2:W9) -> 591.17614 | X6: =_xlfn.STDEV.P('Tutte le stem'!X2:X9) -> 121.79671 | Y6: =_xlfn.STDEV.P('Tutte le stem'!Y2:Y9) -> 6.7631354
A7: COEFFICIENTE DI VARIAZIONE | B7: =B6/B2 -> 0.019886634 | C7: =C6/C2 -> 0.0077516209 | D7: =D6/D2 -> 0.20009884 | E7: =E6/E2 -> 0.060774484 | F7: =F6/F2 -> 0.2099985 | G7: =G6/G2 -> 0.42814036 | H7: =H6/H2 -> 0.12139808 | I7: =I6/I2 -> 0.37226595 | ... Y7: =Y6/Y2 -> 0.31751809
A8: PRIMO QUARTILE | B8: =QUARTILE('Tutte le stem'!E2:E9,1) -> 26.3 | C8: =QUARTILE('Tutte le stem'!F2:F9,1) -> 108.975 | D8: =QUARTILE('Tutte le stem'!G2:G9,1) -> 0.125 | E8: =QUARTILE('Tutte le stem'!K2:K9,1) -> 84.3 | F8: =QUARTILE('Tutte le stem'!L2:L9,1) -> 5.1 | G8: =QUARTILE('Tutte le stem'!M2:M9,1) -> 17.825 | H8: =QUARTILE('Tutte le stem'!N2:N9,1) -> 32.775 | I8: =QUARTILE('Tutte le stem'!O2:O9,1) -> 106.25 | J8: =QUARTILE('Tutte le stem'!P2:P9,1) -> 1396 | K8: =QUARTILE('Tutte le stem'!Q2:Q9,1) -> 41.325 | L8: =QUARTILE('Tutte le stem'!R2:R9,1) -> 49.55 | ... O8: =QUARTILE('Tutte le stem'!U2:U9,1) -> 20.375 | P8: =QUARTILE('Tutte le stem'!B2:B9,1) -> 207 | Q8: =QUARTILE('Tutte le stem'!C2:C9,1) -> 102.75 | R8: =QUARTILE('Tutte le stem'!D2:D9,1) -> 66.075 | S8: =QUARTILE('Tutte le stem'!H2:H9,1) -> 25.275 | T8: =QUARTILE('Tutte le stem'!I2:I9,1) -> 56.15 | U8: =QUARTILE('Tutte le stem'!J2:J9,1) -> 2.5 | V8: =QUARTILE('Tutte le stem'!V2:V9,1) -> 23.925 | W8: =QUARTILE('Tutte le stem'!W2:W9,1) -> 1450.75 | X8: =QUARTILE('Tutte le stem'!X2:X9,1) -> 1356 | Y8: =QUARTILE('Tutte le stem'!Y2:Y9,1) -> 16.5
A9: TERZO QUARTILE | B9: =QUARTILE('Tutte le stem'!E2:E9,3) -> 27.125 | C9: =QUARTILE('Tutte le stem'!F2:F9,3) -> 109.85 | D9: =QUARTILE('Tutte le stem'!G2:G9,3) -> 0.18 | E9: =QUARTILE('Tutte le stem'!K2:K9,3) -> 89.625 | F9: =QUARTILE('Tutte le stem'!L2:L9,3) -> 6.725 | G9: =QUARTILE('Tutte le stem'!M2:M9,3) -> 46.925 | H9: =QUARTILE('Tutte le stem'!N2:N9,3) -> 38.225 | I9: =QUARTILE('Tutte le stem'!O2:O9,3) -> 112.5 | J9: =QUARTILE('Tutte le stem'!P2:P9,3) -> 1498 | K9: =QUARTILE('Tutte le stem'!Q2:Q9,3) -> 55.925 | L9: =QUARTILE('Tutte le stem'!R2:R9,3) -> 57.85 | ... O9: =QUARTILE('Tutte le stem'!U2:U9,3) -> 31.825 | P9: =QUARTILE('Tutte le stem'!B2:B9,3) -> 1052 | Q9: =QUARTILE('Tutte le stem'!C2:C9,3) -> 547.5 | R9: =QUARTILE('Tutte le stem'!D2:D9,3) -> 69.2 | S9: =QUARTILE('Tutte le stem'!H2:H9,3) -> 43.85 | T9: =QUARTILE('Tutte le stem'!I2:I9,3) -> 74.725 | U9: =QUARTILE('Tutte le stem'!J2:J9,3) -> 2.625 | V9: =QUARTILE('Tutte le stem'!V2:V9,3) -> 33.2 | W9: =QUARTILE('Tutte le stem'!W2:W9,3) -> 1575.25 | X9: =QUARTILE('Tutte le stem'!X2:X9,3) -> 1481.75 | Y9: =QUARTILE('Tutte le stem'!Y2:Y9,3) -> 26
A12: Gruppo disciplinare Tecnologico
A13: MEDIA | B13: =AVERAGE('Tutte le stem'!E10:E15) -> 26.833333 | C13: =AVERAGE('Tutte le stem'!F10:F15) -> 107.91667 | D13: =AVERAGE('Tutte le stem'!G10:G15) -> 0.23166667 | E13: =AVERAGE('Tutte le stem'!K10:K15) -> 92 | F13: =AVERAGE('Tutte le stem'!L10:L15) -> 3.4666667 | G13: =AVERAGE('Tutte le stem'!M10:M15) -> 60.9 | H13: =AVERAGE('Tutte le stem'!N10:N15) -> 39.266667 | I13: =AVERAGE('Tutte le stem'!O10:O15) -> 107.05 | J13: =AVERAGE('Tutte le stem'!P10:P15) -> 1600.8333 | K13: =AVERAGE('Tutte le stem'!Q10:Q15) -> 51.316667 | L13: =AVERAGE('Tutte le stem'!R10:R15) -> 59.75 | ... O13: =AVERAGE('Tutte le stem'!U10:U15) -> 21.166667 | P13: =AVERAGE('Tutte le stem'!B10:B15) -> 468.83333 | Q13: =AVERAGE('Tutte le stem'!C10:C15) -> 242.66667 | R13: =AVERAGE('Tutte le stem'!D10:D15) -> 71.333333 | S13: =AVERAGE('Tutte le stem'!H10:H15) -> 60.35 | T13: =AVERAGE('Tutte le stem'!I10:I15) -> 39.65 | U13: =AVERAGE('Tutte le stem'!J10:J15) -> 2.7333333 | V13: =AVERAGE('Tutte le stem'!V10:V15) -> 55.133333 | W13: =AVERAGE('Tutte le stem'!W10:W15) -> 1639.1667 | X13: =AVERAGE('Tutte le stem'!X10:X15) -> 1533.6667 | Y13: =AVERAGE('Tutte le stem'!Y10:Y15) -> 30.416667
A14: MEDIANA | B14: =MEDIAN('Tutte le stem'!E10:E15) -> 26.95 | C14: =MEDIAN('Tutte le stem'!F10:F15) -> 107.9 | D14: =MEDIAN('Tutte le stem'!G10:G15) -> 0.205 | E14: =MEDIAN('Tutte le stem'!K10:K15) -> 93.05 | F14: =MEDIAN('Tutte le stem'!L10:L15) -> 3.35 | G14: =MEDIAN('Tutte le stem'!M10:M15) -> 69.25 | H14: =MEDIAN('Tutte le stem'!N10:N15) -> 40.7 | I14: =MEDIAN('Tutte le stem'!O10:O15) -> 108.75 | J14: =MEDIAN('Tutte le stem'!P10:P15) -> 1590.5 | K14: =MEDIAN('Tutte le stem'!Q10:Q15) -> 50.4 | L14: =MEDIAN('Tutte le stem'!R10:R15) -> 57.75 | ... O14: =MEDIAN('Tutte le stem'!U10:U15) -> 22.1 | P14: =MEDIAN('Tutte le stem'!B10:B15) -> 410 | Q14: =MEDIAN('Tutte le stem'!C10:C15) -> 220 | R14: =MEDIAN('Tutte le stem'!D10:D15) -> 71.15 | S14: =MEDIAN('Tutte le stem'!H10:H15) -> 59.1 | T14: =MEDIAN('Tutte le stem'!I10:I15) -> 40.9 | U14: =MEDIAN('Tutte le stem'!J10:J15) -> 2.7 | V14: =MEDIAN('Tutte le stem'!V10:V15) -> 56.6 | W14: =MEDIAN('Tutte le stem'!W10:W15) -> 1605 | X14: =MEDIAN('Tutte le stem'!X10:X15) -> 1583 | Y14: =MEDIAN('Tutte le stem'!Y10:Y15) -> 29.3
A15: VALORE MINIMO | B15: =MIN('Tutte le stem'!E10:E15) -> 26.1 | C15: =MIN('Tutte le stem'!F10:F15) -> 105.5 | D15: =MIN('Tutte le stem'!G10:G15) -> 0.15 | E15: =MIN('Tutte le stem'!K10:K15) -> 84.3 | F15: =MIN('Tutte le stem'!L10:L15) -> 1.9 | G15: =MIN('Tutte le stem'!M10:M15) -> 35.3 | H15: =MIN('Tutte le stem'!N10:N15) -> 34.5 | I15: =MIN('Tutte le stem'!O10:O15) -> 94 | J15: =MIN('Tutte le stem'!P10:P15) -> 1387 | K15: =MIN('Tutte le stem'!Q10:Q15) -> 44.1 | L15: =MIN('Tutte le stem'!R10:R15) -> 50 | ... O15: =MIN('Tutte le stem'!U10:U15) -> 13.4 | P15: =MIN('Tutte le stem'!B10:B15) -> 210 | Q15: =MIN('Tutte le stem'!C10:C15) -> 143 | R15: =MIN('Tutte le stem'!D10:D15) -> 63.5 | S15: =MIN('Tutte le stem'!H10:H15) -> 47.2 | T15: =MIN('Tutte le stem'!I10:I15) -> 18.1 | U15: =MIN('Tutte le stem'!J10:J15) -> 2.5 | V15: =MIN('Tutte le stem'!V10:V15) -> 26.7 | W15: =MIN('Tutte le stem'!W10:W15) -> 1443 | X15: =MIN('Tutte le stem'!X10:X15) -> 1304 | Y15: =MIN('Tutte le stem'!Y10:Y15) -> 25.9
A16: VALORE MASSIMO | B16: =MAX('Tutte le stem'!E10:E15) -> 27.4 | C16: =MAX('Tutte le stem'!F10:F15) -> 110 | D16: =MAX('Tutte le stem'!G10:G15) -> 0.36 | E16: =MAX('Tutte le stem'!K10:K15) -> 97.2 | F16: =MAX('Tutte le stem'!L10:L15) -> 5.4 | G16: =MAX('Tutte le stem'!M10:M15) -> 77.2 | H16: =MAX('Tutte le stem'!N10:N15) -> 41.1 | I16: =MAX('Tutte le stem'!O10:O15) -> 112.8 | J16: =MAX('Tutte le stem'!P10:P15) -> 1873 | K16: =MAX('Tutte le stem'!Q10:Q15) -> 63.2 | L16: =MAX('Tutte le stem'!R10:R15) -> 71.6 | ... O16: =MAX('Tutte le stem'!U10:U15) -> 27.4 | P16: =MAX('Tutte le stem'!B10:B15) -> 840 | Q16: =MAX('Tutte le stem'!C10:C15) -> 369 | R16: =MAX('Tutte le stem'!D10:D15) -> 85.1 | S16: =MAX('Tutte le stem'!H10:H15) -> 81.9 | T16: =MAX('Tutte le stem'!I10:I15) -> 52.8 | U16: =MAX('Tutte le stem'!J10:J15) -> 3 | V16: =MAX('Tutte le stem'!V10:V15) -> 79.6 | W16: =MAX('Tutte le stem'!W10:W15) -> 1902 | X16: =MAX('Tutte le stem'!X10:X15) -> 1715 | Y16: =MAX('Tutte le stem'!Y10:Y15) -> 40.7
A17: DEVIAZIONE STANDARD | B17: =_xlfn.STDEV.P('Tutte le stem'!E10:E15) -> 0.44969125 | C17: =_xlfn.STDEV.P('Tutte le stem'!F10:F15) -> 1.369205 | D17: =_xlfn.STDEV.P('Tutte le stem'!G10:G15) -> 0.077334052 | E17: =_xlfn.STDEV.P('Tutte le stem'!K10:K15) -> 4.8692915 | F17: =_xlfn.STDEV.P('Tutte le stem'!L10:L15) -> 1.3059692 | G17: =_xlfn.STDEV.P('Tutte le stem'!M10:M15) -> 17.909774 | H17: =_xlfn.STDEV.P('Tutte le stem'!N10:N15) -> 2.4260164 | I17: =_xlfn.STDEV.P('Tutte le stem'!O10:O15) -> 6.10976 | J17: =_xlfn.STDEV.P('Tutte le stem'!P10:P15) -> 177.73427 | K17: =_xlfn.STDEV.P('Tutte le stem'!Q10:Q15) -> 6.7533736 | L17: =_xlfn.STDEV.P('Tutte le stem'!R10:R15) -> 6.9918405 | ... O17: =_xlfn.STDEV.P('Tutte le stem'!U10:U15) -> 5.1989315 | P17: =_xlfn.STDEV.P('Tutte le stem'!B10:B15) -> 217.45836 | Q17: =_xlfn.STDEV.P('Tutte le stem'!C10:C15) -> 93.631666 | R17: =_xlfn.STDEV.P('Tutte le stem'!D10:D15) -> 7.2674312 | S17: =_xlfn.STDEV.P('Tutte le stem'!H10:H15) -> 11.126058 | T17: =_xlfn.STDEV.P('Tutte le stem'!I10:I15) -> 11.126058 | U17: =_xlfn.STDEV.P('Tutte le stem'!J10:J15) -> 0.16996732 | V17: =_xlfn.STDEV.P('Tutte le stem'!V10:V15) -> 22.119047 | W17: =_xlfn.STDEV.P('Tutte le stem'!W10:W15) -> 179.99946 | X17: =_xlfn.STDEV.P('Tutte le stem'!X10:X15) -> 161.72164 | Y17: =_xlfn.STDEV.P('Tutte le stem'!Y10:Y15) -> 4.8447279
A18: COEFFICIENTE DI VARIAZIONE | B18: =B17/B13 -> 0.01675868 | C18: =C17/C13 -> 0.012687614 | D18: =D17/D13 -> 0.33381605 | E18: =E17/E13 -> 0.052927082 | F18: =F17/F13 -> 0.37672189 | G18: =G17/G13 -> 0.29408496 | H18: =H17/H13 -> 0.0617831 | I18: =I17/I13 -> 0.05707389 | ... Y18: =Y17/Y13 -> 0.15927873
A19: PRIMO QUARTILE | B19: =QUARTILE('Tutte le stem'!E10:E15,1) -> 26.525 | C19: =QUARTILE('Tutte le stem'!F10:F15,1) -> 107.5 | D19: =QUARTILE('Tutte le stem'!G10:G15,1) -> 0.17 | E19: =QUARTILE('Tutte le stem'!K10:K15,1) -> 88.325 | F19: =QUARTILE('Tutte le stem'!L10:L15,1) -> 2.3 | G19: =QUARTILE('Tutte le stem'!M10:M15,1) -> 44.05 | H19: =QUARTILE('Tutte le stem'!N10:N15,1) -> 38.45 | I19: =QUARTILE('Tutte le stem'!O10:O15,1) -> 107.5 | J19: =QUARTILE('Tutte le stem'!P10:P15,1) -> 1437.5 | K19: =QUARTILE('Tutte le stem'!Q10:Q15,1) -> 45.2 | L19: =QUARTILE('Tutte le stem'!R10:R15,1) -> 56.275 | ... O19: =QUARTILE('Tutte le stem'!U10:U15,1) -> 16.925 | P19: =QUARTILE('Tutte le stem'!B10:B15,1) -> 309.25 | Q19: =QUARTILE('Tutte le stem'!C10:C15,1) -> 154.75 | R19: =QUARTILE('Tutte le stem'!D10:D15,1) -> 65.275 | S19: =QUARTILE('Tutte le stem'!H10:H15,1) -> 52.675 | T19: =QUARTILE('Tutte le stem'!I10:I15,1) -> 37.025 | U19: =QUARTILE('Tutte le stem'!J10:J15,1) -> 2.625 | V19: =QUARTILE('Tutte le stem'!V10:V15,1) -> 35.775 | W19: =QUARTILE('Tutte le stem'!W10:W15,1) -> 1475.25 | X19: =QUARTILE('Tutte le stem'!X10:X15,1) -> 1391.75 | Y19: =QUARTILE('Tutte le stem'!Y10:Y15,1) -> 27.45
A20: TERZO QUARTILE | B20: =QUARTILE('Tutte le stem'!E10:E15,3) -> 27.15 | C20: =QUARTILE('Tutte le stem'!F10:F15,3) -> 108.6 | D20: =QUARTILE('Tutte le stem'!G10:G15,3) -> 0.285 | E20: =QUARTILE('Tutte le stem'!K10:K15,3) -> 96.5 | F20: =QUARTILE('Tutte le stem'!L10:L15,3) -> 4.475 | G20: =QUARTILE('Tutte le stem'!M10:M15,3) -> 76.375 | H20: =QUARTILE('Tutte le stem'!N10:N15,3) -> 40.85 | I20: =QUARTILE('Tutte le stem'!O10:O15,3) -> 110.375 | J20: =QUARTILE('Tutte le stem'!P10:P15,3) -> 1730.75 | K20: =QUARTILE('Tutte le stem'!Q10:Q15,3) -> 54.85 | L20: =QUARTILE('Tutte le stem'!R10:R15,3) -> 63.65 | ... O20: =QUARTILE('Tutte le stem'!U10:U15,3) -> 25.625 | P20: =QUARTILE('Tutte le stem'!B10:B15,3) -> 603 | Q20: =QUARTILE('Tutte le stem'!C10:C15,3) -> 333.25 | R20: =QUARTILE('Tutte le stem'!D10:D15,3) -> 73.125 | S20: =QUARTILE('Tutte le stem'!H10:H15,3) -> 62.975 | T20: =QUARTILE('Tutte le stem'!I10:I15,3) -> 47.325 | U20: =QUARTILE('Tutte le stem'!J10:J15,3) -> 2.85 | V20: =QUARTILE('Tutte le stem'!V10:V15,3) -> 76 | W20: =QUARTILE('Tutte le stem'!W10:W15,3) -> 1787.25 | X20: =QUARTILE('Tutte le stem'!X10:X15,3) -> 1662.5 | Y20: =QUARTILE('Tutte le stem'!Y10:Y15,3) -> 30.175
A23: Gruppo disciplinare Ingegneria
A24: MEDIA | B24: =AVERAGE('Tutte le stem'!E16:E35) -> 27.23 | C24: =AVERAGE('Tutte le stem'!F16:F35) -> 107.025 | D24: =AVERAGE('Tutte le stem'!G16:G35) -> 0.2975 | E24: =AVERAGE('Tutte le stem'!K16:K35) -> 93.64 | F24: =AVERAGE('Tutte le stem'!L16:L35) -> 2.875 | G24: =AVERAGE('Tutte le stem'!M16:M35) -> 62.535 | H24: =AVERAGE('Tutte le stem'!N16:N35) -> 41.665 | I24: =AVERAGE('Tutte le stem'!O16:O35) -> 107.975 | J24: =AVERAGE('Tutte le stem'!P16:P35) -> 1679.25 | K24: =AVERAGE('Tutte le stem'!Q16:Q35) -> 53.045 | L24: =AVERAGE('Tutte le stem'!R16:R35) -> 62.35 | ... O24: =AVERAGE('Tutte le stem'!U16:U35) -> 19.31 | P24: =AVERAGE('Tutte le stem'!B16:B35) -> 893.65 | Q24: =AVERAGE('Tutte le stem'!C16:C35) -> 464.7 | R24: =AVERAGE('Tutte le stem'!D16:D35) -> 68.675 | S24: =AVERAGE('Tutte le stem'!H16:H35) -> 68.975 | T24: =AVERAGE('Tutte le stem'!I16:I35) -> 31.025 | U24: =AVERAGE('Tutte le stem'!J16:J35) -> 2.945 | V24: =AVERAGE('Tutte le stem'!V16:V35) -> 50.94 | W24: =AVERAGE('Tutte le stem'!W16:W35) -> 1719.35 | X24: =AVERAGE('Tutte le stem'!X16:X35) -> 1602.2 | Y24: =AVERAGE('Tutte le stem'!Y16:Y35) -> 30.66
A25: MEDIANA | B25: =MEDIAN('Tutte le stem'!E16:E35) -> 26.8 | C25: =MEDIAN('Tutte le stem'!F16:F35) -> 106.85 | D25: =MEDIAN('Tutte le stem'!G16:G35) -> 0.285 | E25: =MEDIAN('Tutte le stem'!K16:K35) -> 94.95 | F25: =MEDIAN('Tutte le stem'!L16:L35) -> 2.85 | G25: =MEDIAN('Tutte le stem'!M16:M35) -> 69.7 | H25: =MEDIAN('Tutte le stem'!N16:N35) -> 41.9 | I25: =MEDIAN('Tutte le stem'!O16:O35) -> 105.8 | J25: =MEDIAN('Tutte le stem'!P16:P35) -> 1721.5 | K25: =MEDIAN('Tutte le stem'!Q16:Q35) -> 53.45 | L25: =MEDIAN('Tutte le stem'!R16:R35) -> 64.5 | ... O25: =MEDIAN('Tutte le stem'!U16:U35) -> 18.3 | P25: =MEDIAN('Tutte le stem'!B16:B35) -> 653.5 | Q25: =MEDIAN('Tutte le stem'!C16:C35) -> 347 | R25: =MEDIAN('Tutte le stem'!D16:D35) -> 70.1 | S25: =MEDIAN('Tutte le stem'!H16:H35) -> 68.25 | T25: =MEDIAN('Tutte le stem'!I16:I35) -> 31.75 | U25: =MEDIAN('Tutte le stem'!J16:J35) -> 2.9 | V25: =MEDIAN('Tutte le stem'!V16:V35) -> 50 | W25: =MEDIAN('Tutte le stem'!W16:W35) -> 1717 | X25: =MEDIAN('Tutte le stem'!X16:X35) -> 1640 | Y25: =MEDIAN('Tutte le stem'!Y16:Y35) -> 30.5
A26: VALORE MINIMO | B26: =MIN('Tutte le stem'!E16:E35) -> 26 | C26: =MIN('Tutte le stem'!F16:F35) -> 105.3 | D26: =MIN('Tutte le stem'!G16:G35) -> 0.14 | E26: =MIN('Tutte le stem'!K16:K35) -> 80.2 | F26: =MIN('Tutte le stem'!L16:L35) -> 1.6 | G26: =MIN('Tutte le stem'!M16:M35) -> 21.3 | H26: =MIN('Tutte le stem'!N16:N35) -> 38.5 | I26: =MIN('Tutte le stem'!O16:O35) -> 96.7 | J26: =MIN('Tutte le stem'!P16:P35) -> 1358 | K26: =MIN('Tutte le stem'!Q16:Q35) -> 36.3 | L26: =MIN('Tutte le stem'!R16:R35) -> 36.2 | ... O26: =MIN('Tutte le stem'!U16:U35) -> 13 | P26: =MIN('Tutte le stem'!B16:B35) -> 88 | Q26: =MIN('Tutte le stem'!C16:C35) -> 46 | R26: =MIN('Tutte le stem'!D16:D35) -> 56.6 | S26: =MIN('Tutte le stem'!H16:H35) -> 41.7 | T26: =MIN('Tutte le stem'!I16:I35) -> 7.8 | U26: =MIN('Tutte le stem'!J16:J35) -> 2.5 | V26: =MIN('Tutte le stem'!V16:V35) -> 31.4 | W26: =MIN('Tutte le stem'!W16:W35) -> 1447 | X26: =MIN('Tutte le stem'!X16:X35) -> 1209 | Y26: =MIN('Tutte le stem'!Y16:Y35) -> 16
A27: VALORE MASSIMO | B27: =MAX('Tutte le stem'!E16:E35) -> 30.3 | C27: =MAX('Tutte le stem'!F16:F35) -> 110 | D27: =MAX('Tutte le stem'!G16:G35) -> 0.49 | E27: =MAX('Tutte le stem'!K16:K35) -> 97.7 | F27: =MAX('Tutte le stem'!L16:L35) -> 5.3 | G27: =MAX('Tutte le stem'!M16:M35) -> 86.3 | H27: =MAX('Tutte le stem'!N16:N35) -> 43 | I27: =MAX('Tutte le stem'!O16:O35) -> 132 | J27: =MAX('Tutte le stem'!P16:P35) -> 1849 | K27: =MAX('Tutte le stem'!Q16:Q35) -> 65.4 | L27: =MAX('Tutte le stem'!R16:R35) -> 71.8 | ... O27: =MAX('Tutte le stem'!U16:U35) -> 33.8 | P27: =MAX('Tutte le stem'!B16:B35) -> 2687 | Q27: =MAX('Tutte le stem'!C16:C35) -> 1398 | R27: =MAX('Tutte le stem'!D16:D35) -> 77.8 | S27: =MAX('Tutte le stem'!H16:H35) -> 92.2 | T27: =MAX('Tutte le stem'!I16:I35) -> 58.3 | U27: =MAX('Tutte le stem'!J16:J35) -> 3.4 | V27: =MAX('Tutte le stem'!V16:V35) -> 78.7 | W27: =MAX('Tutte le stem'!W16:W35) -> 1880 | X27: =MAX('Tutte le stem'!X16:X35) -> 1819 | Y27: =MAX('Tutte le stem'!Y16:Y35) -> 43.3
A28: DEVIAZIONE STANDARD | B28: =_xlfn.STDEV.P('Tutte le stem'!E16:E35) -> 1.0464703 | C28: =_xlfn.STDEV.P('Tutte le stem'!F16:F35) -> 1.200781 | D28: =_xlfn.STDEV.P('Tutte le stem'!G16:G35) -> 0.080676824 | E28: =_xlfn.STDEV.P('Tutte le stem'!K16:K35) -> 4.427121 | F28: =_xlfn.STDEV.P('Tutte le stem'!L16:L35) -> 0.97819988 | G28: =_xlfn.STDEV.P('Tutte le stem'!M16:M35) -> 20.948324 | H28: =_xlfn.STDEV.P('Tutte le stem'!N16:N35) -> 1.1512059 | I28: =_xlfn.STDEV.P('Tutte le stem'!O16:O35) -> 8.5728569 | J28: =_xlfn.STDEV.P('Tutte le stem'!P16:P35) -> 138.64122 | K28: =_xlfn.STDEV.P('Tutte le stem'!Q16:Q35) -> 7.4654856 | L28: =_xlfn.STDEV.P('Tutte le stem'!R16:R35) -> 8.4372093 | ... O28: =_xlfn.STDEV.P('Tutte le stem'!U16:U35) -> 4.3468264 | P28: =_xlfn.STDEV.P('Tutte le stem'!B16:B35) -> 744.39628 | Q28: =_xlfn.STDEV.P('Tutte le stem'!C16:C35) -> 394.82656 | R28: =_xlfn.STDEV.P('Tutte le stem'!D16:D35) -> 5.0299975 | S28: =_xlfn.STDEV.P('Tutte le stem'!H16:H35) -> 16.28416 | T28: =_xlfn.STDEV.P('Tutte le stem'!I16:I35) -> 16.28416 | U28: =_xlfn.STDEV.P('Tutte le stem'!J16:J35) -> 0.20365412 | V28: =_xlfn.STDEV.P('Tutte le stem'!V16:V35) -> 12.921432 | W28: =_xlfn.STDEV.P('Tutte le stem'!W16:W35) -> 109.5743 | X28: =_xlfn.STDEV.P('Tutte le stem'!X16:X35) -> 159.24403 | Y28: =_xlfn.STDEV.P('Tutte le stem'!Y16:Y35) -> 7.5255166
A29: COEFFICIENTE DI VARIAZIONE | B29: =B28/B24 -> 0.038430784 | C29: =C28/C24 -> 0.011219631 | D29: =D28/D24 -> 0.2711826 | E29: =E28/E24 -> 0.047278097 | F29: =F28/F24 -> 0.34024344 | G29: =G28/G24 -> 0.33498559 | H29: =H28/H24 -> 0.027630047 | I29: =I28/I24 -> 0.079396683 | ... Y29: =Y28/Y24 -> 0.24545064
A30: PRIMO QUARTILE | B30: =QUARTILE('Tutte le stem'!E16:E35,1) -> 26.475 | C30: =QUARTILE('Tutte le stem'!F16:F35,1) -> 106.35 | D30: =QUARTILE('Tutte le stem'!G16:G35,1) -> 0.25 | E30: =QUARTILE('Tutte le stem'!K16:K35,1) -> 93.9 | F30: =QUARTILE('Tutte le stem'!L16:L35,1) -> 2.1 | G30: =QUARTILE('Tutte le stem'!M16:M35,1) -> 48.95 | H30: =QUARTILE('Tutte le stem'!N16:N35,1) -> 41.475 | I30: =QUARTILE('Tutte le stem'!O16:O35,1) -> 103 | J30: =QUARTILE('Tutte le stem'!P16:P35,1) -> 1631 | K30: =QUARTILE('Tutte le stem'!Q16:Q35,1) -> 49.325 | L30: =QUARTILE('Tutte le stem'!R16:R35,1) -> 62.625 | ... O30: =QUARTILE('Tutte le stem'!U16:U35,1) -> 17.15 | P30: =QUARTILE('Tutte le stem'!B16:B35,1) -> 396.75 | Q30: =QUARTILE('Tutte le stem'!C16:C35,1) -> 187.5 | R30: =QUARTILE('Tutte le stem'!D16:D35,1) -> 65 | S30: =QUARTILE('Tutte le stem'!H16:H35,1) -> 57.225 | T30: =QUARTILE('Tutte le stem'!I16:I35,1) -> 14.85 | U30: =QUARTILE('Tutte le stem'!J16:J35,1) -> 2.875 | V30: =QUARTILE('Tutte le stem'!V16:V35,1) -> 39.275 | W30: =QUARTILE('Tutte le stem'!W16:W35,1) -> 1649.25 | X30: =QUARTILE('Tutte le stem'!X16:X35,1) -> 1546.75 | Y30: =QUARTILE('Tutte le stem'!Y16:Y35,1) -> 27.2
A31: TERZO QUARTILE | B31: =QUARTILE('Tutte le stem'!E16:E35,3) -> 27.525 | C31: =QUARTILE('Tutte le stem'!F16:F35,3) -> 107.6 | D31: =QUARTILE('Tutte le stem'!G16:G35,3) -> 0.3425 | E31: =QUARTILE('Tutte le stem'!K16:K35,3) -> 96.6 | F31: =QUARTILE('Tutte le stem'!L16:L35,3) -> 3.125 | G31: =QUARTILE('Tutte le stem'!M16:M35,3) -> 79.775 | H31: =QUARTILE('Tutte le stem'!N16:N35,3) -> 42.425 | I31: =QUARTILE('Tutte le stem'!O16:O35,3) -> 109.8 | J31: =QUARTILE('Tutte le stem'!P16:P35,3) -> 1757.25 | K31: =QUARTILE('Tutte le stem'!Q16:Q35,3) -> 58.125 | L31: =QUARTILE('Tutte le stem'!R16:R35,3) -> 66.725 | ... O31: =QUARTILE('Tutte le stem'!U16:U35,3) -> 20.6 | P31: =QUARTILE('Tutte le stem'!B16:B35,3) -> 1029.25 | Q31: =QUARTILE('Tutte le stem'!C16:C35,3) -> 535.25 | R31: =QUARTILE('Tutte le stem'!D16:D35,3) -> 71.95 | S31: =QUARTILE('Tutte le stem'!H16:H35,3) -> 85.15 | T31: =QUARTILE('Tutte le stem'!I16:I35,3) -> 42.775 | U31: =QUARTILE('Tutte le stem'!J16:J35,3) -> 3.1 | V31: =QUARTILE('Tutte le stem'!V16:V35,3) -> 59.8 | W31: =QUARTILE('Tutte le stem'!W16:W35,3) -> 1790.75 | X31: =QUARTILE('Tutte le stem'!X16:X35,3) -> 1713 | Y31: =QUARTILE('Tutte le stem'!Y16:Y35,3) -> 35.975
A34: Gruppo disciplinare Matematico
A35: MEDIA | B35: =AVERAGE('Tutte le stem'!E36:E37) -> 26.25 | C35: =AVERAGE('Tutte le stem'!F36:F37) -> 109.75 | D35: =AVERAGE('Tutte le stem'!G36:G37) -> 0.235 | E35: =AVERAGE('Tutte le stem'!K36:K37) -> 94.95 | F35: =AVERAGE('Tutte le stem'!L36:L37) -> 2.7 | G35: =AVERAGE('Tutte le stem'!M36:M37) -> 48.85 | H35: =AVERAGE('Tutte le stem'!N36:N37) -> 34.8 | I35: =AVERAGE('Tutte le stem'!O36:O37) -> 108.2 | J35: =AVERAGE('Tutte le stem'!P36:P37) -> 1600 | K35: =AVERAGE('Tutte le stem'!Q36:Q37) -> 45.85 | L35: =AVERAGE('Tutte le stem'!R36:R37) -> 62.65 | ... O35: =AVERAGE('Tutte le stem'!U36:U37) -> 14.15 | P35: =AVERAGE('Tutte le stem'!B36:B37) -> 1016.5 | Q35: =AVERAGE('Tutte le stem'!C36:C37) -> 550 | R35: =AVERAGE('Tutte le stem'!D36:D37) -> 72.7 | S35: =AVERAGE('Tutte le stem'!H36:H37) -> 59.7 | T35: =AVERAGE('Tutte le stem'!I36:I37) -> 40.3 | U35: =AVERAGE('Tutte le stem'!J36:J37) -> 2.7 | V35: =AVERAGE('Tutte le stem'!V36:V37) -> 63.8 | W35: =AVERAGE('Tutte le stem'!W36:W37) -> 1656 | X35: =AVERAGE('Tutte le stem'!X36:X37) -> 1530.5 | Y35: =AVERAGE('Tutte le stem'!Y36:Y37) -> 32.35
A36: MEDIANA | B36: =MEDIAN('Tutte le stem'!E35:E37) -> 26.4 | C36: =MEDIAN('Tutte le stem'!F35:F37) -> 109.2 | D36: =MEDIAN('Tutte le stem'!G35:G37) -> 0.23 | E36: =MEDIAN('Tutte le stem'!K35:K37) -> 95.6 | F36: =MEDIAN('Tutte le stem'!L35:L37) -> 2.9 | G36: =MEDIAN('Tutte le stem'!M35:M37) -> 52.8 | H36: =MEDIAN('Tutte le stem'!N35:N37) -> 37.2 | I36: =MEDIAN('Tutte le stem'!O35:O37) -> 108.6 | J36: =MEDIAN('Tutte le stem'!P35:P37) -> 1633 | K36: =MEDIAN('Tutte le stem'!Q35:Q37) -> 47.8 | L36: =MEDIAN('Tutte le stem'!R35:R37) -> 62.8 | ... O36: =MEDIAN('Tutte le stem'!U35:U37) -> 14.9 | P36: =MEDIAN('Tutte le stem'!B35:B37) -> 999 | Q36: =MEDIAN('Tutte le stem'!C35:C37) -> 543 | R36: =MEDIAN('Tutte le stem'!D35:D37) -> 73 | S36: =MEDIAN('Tutte le stem'!H35:H37) -> 63.6 | T36: =MEDIAN('Tutte le stem'!I35:I37) -> 36.4 | U36: =MEDIAN('Tutte le stem'!J35:J37) -> 2.7 | V36: =MEDIAN('Tutte le stem'!V35:V37) -> 63.7 | W36: =MEDIAN('Tutte le stem'!W35:W37) -> 1666 | X36: =MEDIAN('Tutte le stem'!X35:X37) -> 1515 | Y36: =MEDIAN('Tutte le stem'!Y35:Y37) -> 32.9
A37: VALORE MINIMO | B37: =MIN('Tutte le stem'!E35:E37) -> 26.1 | C37: =MIN('Tutte le stem'!F35:F37) -> 105.3 | D37: =MIN('Tutte le stem'!G35:G37) -> 0.2 | E37: =MIN('Tutte le stem'!K35:K37) -> 94.3 | F37: =MIN('Tutte le stem'!L35:L37) -> 2.5 | G37: =MIN('Tutte le stem'!M35:M37) -> 44.9 | H37: =MIN('Tutte le stem'!N35:N37) -> 32.4 | I37: =MIN('Tutte le stem'!O35:O37) -> 107.8 | J37: =MIN('Tutte le stem'!P35:P37) -> 1567 | K37: =MIN('Tutte le stem'!Q35:Q37) -> 43.9 | L37: =MIN('Tutte le stem'!R35:R37) -> 61.4 | ... O37: =MIN('Tutte le stem'!U35:U37) -> 13.4 | P37: =MIN('Tutte le stem'!B35:B37) -> 88 | Q37: =MIN('Tutte le stem'!C35:C37) -> 46 | R37: =MIN('Tutte le stem'!D35:D37) -> 71.9 | S37: =MIN('Tutte le stem'!H35:H37) -> 47.4 | T37: =MIN('Tutte le stem'!I35:I37) -> 28 | U37: =MIN('Tutte le stem'!J35:J37) -> 2.7 | V37: =MIN('Tutte le stem'!V35:V37) -> 39.5 | W37: =MIN('Tutte le stem'!W35:W37) -> 1646 | X37: =MIN('Tutte le stem'!X35:X37) -> 1459 | Y37: =MIN('Tutte le stem'!Y35:Y37) -> 31.8
A38: VALORE MASSIMO | B38: =MAX('Tutte le stem'!E35:E37) -> 30.3 | C38: =MAX('Tutte le stem'!F35:F37) -> 110.3 | D38: =MAX('Tutte le stem'!G35:G37) -> 0.24 | E38: =MAX('Tutte le stem'!K35:K37) -> 95.7 | F38: =MAX('Tutte le stem'!L35:L37) -> 3.1 | G38: =MAX('Tutte le stem'!M35:M37) -> 53.5 | H38: =MAX('Tutte le stem'!N35:N37) -> 42.7 | I38: =MAX('Tutte le stem'!O35:O37) -> 128 | J38: =MAX('Tutte le stem'!P35:P37) -> 1741 | K38: =MAX('Tutte le stem'!Q35:Q37) -> 58.1 | L38: =MAX('Tutte le stem'!R35:R37) -> 63.9 | ... O38: =MAX('Tutte le stem'!U35:U37) -> 20.9 | P38: =MAX('Tutte le stem'!B35:B37) -> 1034 | Q38: =MAX('Tutte le stem'!C35:C37) -> 557 | R38: =MAX('Tutte le stem'!D35:D37) -> 73.5 | S38: =MAX('Tutte le stem'!H35:H37) -> 72 | T38: =MAX('Tutte le stem'!I35:I37) -> 52.6 | U38: =MAX('Tutte le stem'!J35:J37) -> 2.7 | V38: =MAX('Tutte le stem'!V35:V37) -> 63.9 | W38: =MAX('Tutte le stem'!W35:W37) -> 1871 | X38: =MAX('Tutte le stem'!X35:X37) -> 1546 | Y38: =MAX('Tutte le stem'!Y35:Y37) -> 35.7
A39: DEVIAZIONE STANDARD | B39: =_xlfn.STDEV.P('Tutte le stem'!E35:E37) -> 1.9131126 | C39: =_xlfn.STDEV.P('Tutte le stem'!F35:F37) -> 2.1452791 | D39: =_xlfn.STDEV.P('Tutte le stem'!G35:G37) -> 0.016996732 | E39: =_xlfn.STDEV.P('Tutte le stem'!K35:K37) -> 0.63770422 | F39: =_xlfn.STDEV.P('Tutte le stem'!L35:L37) -> 0.24944383 | G39: =_xlfn.STDEV.P('Tutte le stem'!M35:M37) -> 3.8995726 | H39: =_xlfn.STDEV.P('Tutte le stem'!N35:N37) -> 4.2081931 | I39: =_xlfn.STDEV.P('Tutte le stem'!O35:O37) -> 9.3395218 | J39: =_xlfn.STDEV.P('Tutte le stem'!P35:P37) -> 71.721684 | K39: =_xlfn.STDEV.P('Tutte le stem'!Q35:Q37) -> 5.9901771 | L39: =_xlfn.STDEV.P('Tutte le stem'!R35:R37) -> 1.0230673 | ... O39: =_xlfn.STDEV.P('Tutte le stem'!U35:U37) -> 3.2403703 | P39: =_xlfn.STDEV.P('Tutte le stem'!B35:B37) -> 437.93226 | Q39: =_xlfn.STDEV.P('Tutte le stem'!C35:C37) -> 237.65662 | R39: =_xlfn.STDEV.P('Tutte le stem'!D35:D37) -> 0.66833126 | S39: =_xlfn.STDEV.P('Tutte le stem'!H35:H37) -> 10.209799 | T39: =_xlfn.STDEV.P('Tutte le stem'!I35:I37) -> 10.209799 | U39: =_xlfn.STDEV.P('Tutte le stem'!J35:J37) -> 4.4408921e-16 | V39: =_xlfn.STDEV.P('Tutte le stem'!V35:V37) -> 11.455421 | W39: =_xlfn.STDEV.P('Tutte le stem'!W35:W37) -> 101.68033 | X39: =_xlfn.STDEV.P('Tutte le stem'!X35:X37) -> 36.003086 | Y39: =_xlfn.STDEV.P('Tutte le stem'!Y35:Y37) -> 1.6418147
A40: COEFFICIENTE DI VARIAZIONE | B40: =B39/B35 -> 0.072880482 | C40: =C39/C35 -> 0.019546962 | D40: =D39/D35 -> 0.072326518 | E40: =E39/E35 -> 0.0067162108 | F40: =F39/F35 -> 0.092386602 | G40: =G39/G35 -> 0.079827485 | H40: =H39/H35 -> 0.12092509 | I40: =I39/I35 -> 0.086317207 | ... Y40: =Y39/Y35 -> 0.050751614
A41: PRIMO QUARTILE | B41: =QUARTILE('Tutte le stem'!E35:E37,1) -> 26.25 | C41: =QUARTILE('Tutte le stem'!F35:F37,1) -> 107.25 | D41: =QUARTILE('Tutte le stem'!G35:G37,1) -> 0.215 | E41: =QUARTILE('Tutte le stem'!K35:K37,1) -> 94.95 | F41: =QUARTILE('Tutte le stem'!L35:L37,1) -> 2.7 | G41: =QUARTILE('Tutte le stem'!M35:M37,1) -> 48.85 | H41: =QUARTILE('Tutte le stem'!N35:N37,1) -> 34.8 | I41: =QUARTILE('Tutte le stem'!O35:O37,1) -> 108.2 | J41: =QUARTILE('Tutte le stem'!P35:P37,1) -> 1600 | K41: =QUARTILE('Tutte le stem'!Q35:Q37,1) -> 45.85 | L41: =QUARTILE('Tutte le stem'!R35:R37,1) -> 62.1 | ... O41: =QUARTILE('Tutte le stem'!U35:U37,1) -> 14.15 | P41: =QUARTILE('Tutte le stem'!B35:B37,1) -> 543.5 | Q41: =QUARTILE('Tutte le stem'!C35:C37,1) -> 294.5 | R41: =QUARTILE('Tutte le stem'!D35:D37,1) -> 72.45 | S41: =QUARTILE('Tutte le stem'!H35:H37,1) -> 55.5 | T41: =QUARTILE('Tutte le stem'!I35:I37,1) -> 32.2 | U41: =QUARTILE('Tutte le stem'!J35:J37,1) -> 2.7 | V41: =QUARTILE('Tutte le stem'!V35:V37,1) -> 51.6 | W41: =QUARTILE('Tutte le stem'!W35:W37,1) -> 1656 | X41: =QUARTILE('Tutte le stem'!X35:X37,1) -> 1487 | Y41: =QUARTILE('Tutte le stem'!Y35:Y37,1) -> 32.35
A42: TERZO QUARTILE | B42: =QUARTILE('Tutte le stem'!E35:E37,3) -> 28.35 | C42: =QUARTILE('Tutte le stem'!F35:F37,3) -> 109.75 | D42: =QUARTILE('Tutte le stem'!G35:G37,3) -> 0.235 | E42: =QUARTILE('Tutte le stem'!K35:K37,3) -> 95.65 | F42: =QUARTILE('Tutte le stem'!L35:L37,3) -> 3 | G42: =QUARTILE('Tutte le stem'!M35:M37,3) -> 53.15 | H42: =QUARTILE('Tutte le stem'!N35:N37,3) -> 39.95 | I42: =QUARTILE('Tutte le stem'!O35:O37,3) -> 118.3 | J42: =QUARTILE('Tutte le stem'!P35:P37,3) -> 1687 | K42: =QUARTILE('Tutte le stem'!Q35:Q37,3) -> 52.95 | L42: =QUARTILE('Tutte le stem'!R35:R37,3) -> 63.35 | ... O42: =QUARTILE('Tutte le stem'!U35:U37,3) -> 17.9 | P42: =QUARTILE('Tutte le stem'!B35:B37,3) -> 1016.5 | Q42: =QUARTILE('Tutte le stem'!C35:C37,3) -> 550 | R42: =QUARTILE('Tutte le stem'!D35:D37,3) -> 73.25 | S42: =QUARTILE('Tutte le stem'!H35:H37,3) -> 67.8 | T42: =QUARTILE('Tutte le stem'!I35:I37,3) -> 44.5 | U42: =QUARTILE('Tutte le stem'!J35:J37,3) -> 2.7 | V42: =QUARTILE('Tutte le stem'!V35:V37,3) -> 63.8 | W42: =QUARTILE('Tutte le stem'!W35:W37,3) -> 1768.5 | X42: =QUARTILE('Tutte le stem'!X35:X37,3) -> 1530.5 | Y42: =QUARTILE('Tutte le stem'!Y35:Y37,3) -> 34.3
A45: Indici di posizione dei singoli gruppi stem | B45: età alla laurea | C45: voto di laurea | D45: indice di ritardo | E45: tasso di occupazione | F45: tempo dall'inizio della ricerca al reperimento del primo lavoro | G45: tempo indeterminato | H45: numero di ore di lavoro settimanali | I45: gender gap retribuzione | J45: retribuzione mensile netta totale | K45: utilizzo elevato delle competenze acquisite | L45: adeguatezza della formazione professionale acquisita all'università : molto adeguata | M45: laurea molto efficace per il lavoro svolto | N45: soddisfazione lavoro svolto | O45: occupati che cercano lavoro | P45: Numero di laureati | Q45: Numero di intervistati | R45: Tasso di risposta sui laureati contattabili | S45: % Uomini | T45: % Donne | U45: durata degli studi | V45: diffusione smart working | W45: retribuzione mensile netta uomini | X45: retribuzione mensile netta donne | Y45: laurea abbastanza efficace per il lavoro svolto
A46: MEDIA | B46: 27.022222 | C46: 107.82222 | D46: 0.25 | E46: 91.769444 | F46: 3.6527778 | G46: 55.280556 | H46: 39.288889 | I46: 111.31944 | J46: 1606.5 | K46: 51.586111 | L46: 59.658333 | M46: 62.677778 | N46: 7.7833333 | O46: 20.886111 | P46: 828.88889 | Q46: 432.44444 | R46: 68.941667 | S46: 59.369444 | T46: 40.630556 | U46: 2.8083333 | V46: 47.436111 | W46: 1699.4167 | X46: 1540.1389 | Y46: 28.633333
A47: MEDIANA | B47: 26.8 | C47: 107.65 | D47: 0.235 | E47: 94.35 | F47: 3.05 | G47: 53.85 | H47: 41.1 | I47: 106.95 | J47: 1639.5 | K47: 52.85 | L47: 62.45 | M47: 62.45 | N47: 7.8 | O47: 20.25 | P47: 642 | Q47: 347 | R47: 69.9 | S47: 58.85 | T47: 41.15 | U47: 2.75 | V47: 44.6 | W47: 1680.5 | X47: 1571 | Y47: 29.25
A48: VALORE MINIMO | B48: 26 | C48: 105.3 | D48: 0.11 | E48: 73.8 | F48: 1.6 | G48: 16.7 | H48: 25.4 | I48: 93.1 | J48: 1193 | K48: 27.8 | L48: 35.7 | M48: 31.3 | N48: 7.4 | O48: 10.5 | P48: 88 | Q48: 42 | R48: 56.6 | S48: 18.3 | T48: 7.8 | U48: 2.4 | V48: 16.7 | W48: 1278 | X48: 1121 | Y48: 10.2
...
